## panic

错误主要分为两类，一类不可恢复的，另一类可恢复的。调用panic！ 相当于不可恢复的错误。通过返回result，这种错误相当于进行传播，错误是可恢复的。

### 什么时候使用panic

* 在定义一个可能失败的的函数时，优先考虑返回Result。
* 否则就panic。

### 编写示例、原型代码、测试
* 可以使用 panic
    * 演示某些概念：unwrap
    * 原型代码：unwrap、expect
    * 测试：unwrap,expect
* 确定Result 就是 ok：unwrap
    ```
    fn main() {
        let home: IpAddr = "127.0.0.1".parse().unwrap(); 
        println!("{}", home);
    }
    ```
* 当代码最终可能处于损坏状态时，最好使用panic
* 损坏状态（bad state):某些假设、保证、约定或不可变性被打破。
    * 例如非法的值、矛盾的值或空缺的值被传入代码
    * 以及下列中的一条：
        * 这种损坏状态并不是预期能够偶尔发生的事情。
        * 在此之后，代码如果处于这种损坏状态则无法运行
        * 使用的类型中，没有一个好的方法来将这些信息（处于损坏状态）进行编码
    
### 场景分析
* 调用你的代码，传入无意义的参数：panic!
* 调用外部不可控代码，返回非法状态，你无法修复：panic!
* 如果失败是可预期的， Result
* 当你的代码对值进行操作，首先应该验证这些值，如果无效  panic!

### 为验证创建自定义类型

* 创建新的类型，把验证逻辑放在构造实例的函数中
```
pub struct Guess {
    value: i32,
}

impl Guess {
    pub fn new(value: i32) -> Guess {
        if value < 1 || value > 100 {
            panic!("guess value must be between 1 and 100");
        }
        Guess { value: value }
    }

    pub fn value(&self) -> i32 {
        self.value
    }
}

fn main() {
    loop {
        let guess = "32";
        let guess: i32 = match guess.trim().parse() {
            Ok(num) => num,
            Err(_) => continue,
        };
        let guess = Guess::new(guess);
        //...
    }
}
```