## 测试中使用 Result<T,E>

* 无需panic,可使用Result<T,E> 作为返回类型编写测试
    * 返回 ok：测试通过
    * 返回 Err：测试失败

测试 ok
```
#[cfg(test)]
mod tests {
    #[test]
    fn it_works() ->Result<(), String> {
        if 2+2 ==4 {
            Ok(())
        } else {
            Err(String::from("two plus two dose not equal four"))
        }
    }
}
```
测试 FAILED
```
#[cfg(test)]
mod tests {
    #[test]
    fn it_works() ->Result<(), String> {
        if 2+3 ==4 {
            Ok(())
        } else {
            Err(String::from("two plus two dose not equal four"))
        }
    }
}
```

失败消息
```
base_learn11-04 git:(master) ✗ cargo  test
   Compiling base_learn11-04 v0.1.0 (/Users/lucky/data/rust/study/base_learn11-04)
    Finished test [unoptimized + debuginfo] target(s) in 0.72s
     Running target/debug/deps/base_learn11_04-950ede8b46196793

running 1 test
test tests::it_works ... FAILED

failures:

---- tests::it_works stdout ----
Error: "two plus two dose not equal four"
thread 'tests::it_works' panicked at 'assertion failed: `(left == right)`
  left: `1`,
 right: `0`: the test returned a termination value with a non-zero status code (1) which indicates a failure', /Users/lucky/.rustup/toolchains/stable-x86_64-apple-darwin/lib/rustlib/src/rust/library/test/src/lib.rs:192:5
note: run with `RUST_BACKTRACE=1` environment variable to display a backtrace


failures:
    tests::it_works

test result: FAILED. 0 passed; 1 failed; 0 ignored; 0 measured; 0 filtered out
```